2020-04-16 17:02:33,753 [INFO ]  Starting Rasa server on http://localhost:5005
2020-04-16 17:02:45,372 [ERROR]  Exception occurred while handling uri: 'http://localhost:5005/favicon.ico'
Traceback (most recent call last):
  File "/usr/local/lib/python3.7/site-packages/sanic/app.py", line 940, in handle_request
    handler, args, kwargs, uri, name = self.router.get(request)
  File "/usr/local/lib/python3.7/site-packages/sanic/router.py", line 411, in get
    return self._get(request.path, request.method, "")
  File "/usr/local/lib/python3.7/site-packages/sanic/router.py", line 475, in _get
    raise NotFound("Requested URL {} not found".format(url))
sanic.exceptions.NotFound: Requested URL /favicon.ico not found
2020-04-16 17:03:45,105 [ERROR]  Exception occurred while handling uri: unknown
NoneType: None
